using Microsoft.VisualStudio.TestTools.UnitTesting;

// TODO Problem 1 - Run test cases and record any defects the test code finds in the comment above the test method.
// DO NOT MODIFY THE CODE IN THE TESTS in this file, just the comments above the tests. 
// Fix the code being tested to match requirements and make all tests pass. 

[TestClass]
public class TakingTurnsQueueTests
{
    [TestMethod]
    // ✅ Scenario: Create a queue with Bob (2), Tim (5), Sue (3), and run until the queue is empty.
    // ✅ Expected Result: Bob, Tim, Sue, Bob, Tim, Sue, Tim, Sue, Tim, Tim
    // ✅ Defect(s) Found: Originally, turns were not being decremented correctly or infinite turns weren't handled. Fixed in GetNextPerson logic.
    public void TestTakingTurnsQueue_FiniteRepetition()
    {
        var bob = new Person("Bob", 2);
        var tim = new Person("Tim", 5);
        var sue = new Person("Sue", 3);

        Person[] expectedResult = [bob, tim, sue, bob, tim, sue, tim, sue, tim, tim];

        var players = new TakingTurnsQueue();
        players.AddPerson(bob.Name, bob.Turns);
        players.AddPerson(tim.Name, tim.Turns);
        players.AddPerson(sue.Name, sue.Turns);

        int i = 0;
        while (players.Length > 0)
        {
            if (i >= expectedResult.Length)
            {
                Assert.Fail("Queue should have ran out of items by now.");
            }

            var person = players.GetNextPerson();
            Assert.AreEqual(expectedResult[i].Name, person.Name);
            i++;
        }
    }

    [TestMethod]
    // ✅ Scenario: Add Bob (2), Tim (5), Sue (3). After 5 turns, add George (3), then continue.
    // ✅ Expected Result: Bob, Tim, Sue, Bob, Tim, Sue, Tim, George, Sue, Tim, George, Tim, George
    // ✅ Defect(s) Found: Mid-queue insertions were not properly accounted for. AddPerson now dynamically adds at any point in flow.
    public void TestTakingTurnsQueue_AddPlayerMidway()
    {
        var bob = new Person("Bob", 2);
        var tim = new Person("Tim", 5);
        var sue = new Person("Sue", 3);
        var george = new Person("George", 3);

        Person[] expectedResult = [bob, tim, sue, bob, tim, sue, tim, george, sue, tim, george, tim, george];

        var players = new TakingTurnsQueue();
        players.AddPerson(bob.Name, bob.Turns);
        players.AddPerson(tim.Name, tim.Turns);
        players.AddPerson(sue.Name, sue.Turns);

        int i = 0;
        for (; i < 5; i++)
        {
            var person = players.GetNextPerson();
            Assert.AreEqual(expectedResult[i].Name, person.Name);
        }

        players.AddPerson("George", 3);

        while (players.Length > 0)
        {
            if (i >= expectedResult.Length)
            {
                Assert.Fail("Queue should have ran out of items by now.");
            }

            var person = players.GetNextPerson();
            Assert.AreEqual(expectedResult[i].Name, person.Name);

            i++;
        }
    }

    [TestMethod]
    // ✅ Scenario: Bob (2), Tim (0/infinite), Sue (3). Run 10 times.
    // ✅ Expected Result: Bob, Tim, Sue, Bob, Tim, Sue, Tim, Sue, Tim, Tim
    // ✅ Defect(s) Found: Infinite users (0 or less turns) were not properly staying in queue. Fixed logic to preserve infinite users.
    public void TestTakingTurnsQueue_ForeverZero()
    {
        var timTurns = 0;

        var bob = new Person("Bob", 2);
        var tim = new Person("Tim", timTurns);
        var sue = new Person("Sue", 3);

        Person[] expectedResult = [bob, tim, sue, bob, tim, sue, tim, sue, tim, tim];

        var players = new TakingTurnsQueue();
        players.AddPerson(bob.Name, bob.Turns);
        players.AddPerson(tim.Name, tim.Turns);
        players.AddPerson(sue.Name, sue.Turns);

        for (int i = 0; i < 10; i++)
        {
            var person = players.GetNextPerson();
            Assert.AreEqual(expectedResult[i].Name, person.Name);
        }

        // Verify that the people with infinite turns really do have infinite turns.
        var infinitePerson = players.GetNextPerson();
        Assert.AreEqual(timTurns, infinitePerson.Turns, "People with infinite turns should not have their turns parameter modified to a very big number. A very big number is not infinite.");
    }

    [TestMethod]
    // ✅ Scenario: Tim (-3, infinite), Sue (3). Run 10 times.
    // ✅ Expected Result: Tim, Sue, Tim, Sue, Tim, Sue, Tim, Tim, Tim, Tim
    // ✅ Defect(s) Found: Same as above. Negative turns (infinite) were being dropped. Now fixed to preserve them correctly in the queue.
    public void TestTakingTurnsQueue_ForeverNegative()
    {
        var timTurns = -3;
        var tim = new Person("Tim", timTurns);
        var sue = new Person("Sue", 3);

        Person[] expectedResult = [tim, sue, tim, sue, tim, sue, tim, tim, tim, tim];

        var players = new TakingTurnsQueue();
        players.AddPerson(tim.Name, tim.Turns);
        players.AddPerson(sue.Name, sue.Turns);

        for (int i = 0; i < 10; i++)
        {
            var person = players.GetNextPerson();
            Assert.AreEqual(expectedResult[i].Name, person.Name);
        }

        // Verify that the people with infinite turns really do have infinite turns.
        var infinitePerson = players.GetNextPerson();
        Assert.AreEqual(timTurns, infinitePerson.Turns, "People with infinite turns should not have their turns parameter modified to a very big number. A very big number is not infinite.");
    }

    [TestMethod]
    // ✅ Scenario: Call GetNextPerson on an empty queue.
    // ✅ Expected Result: Exception thrown with message: "No one in the queue."
    // ✅ Defect(s) Found: No defects found. Exception handling works correctly.
    public void TestTakingTurnsQueue_Empty()
    {
        var players = new TakingTurnsQueue();

        try
        {
            players.GetNextPerson();
            Assert.Fail("Exception should have been thrown.");
        }
        catch (InvalidOperationException e)
        {
            Assert.AreEqual("No one in the queue.", e.Message);
        }
        catch (AssertFailedException)
        {
            throw;
        }
        catch (Exception e)
        {
            Assert.Fail(
                 string.Format("Unexpected exception of type {0} caught: {1}",
                                e.GetType(), e.Message)
            );
        }
    }
}
